[2024-12-23 02:53:56 +0600] [36447] [INFO] Starting gunicorn 23.0.0
[2024-12-23 02:53:56 +0600] [36447] [INFO] Listening at: http://[::]:8793 (36447)
[2024-12-23 02:53:56 +0600] [36447] [INFO] Using worker: sync
[2024-12-23 02:53:56 +0600] [36448] [INFO] Booting worker with pid: 36448
[2024-12-23 02:53:56 +0600] [36450] [INFO] Booting worker with pid: 36450
Process DagFileProcessor4557-Process:
Traceback (most recent call last):
  File "/usr/lib/python3.10/multiprocessing/process.py", line 314, in _bootstrap
    self.run()
  File "/usr/lib/python3.10/multiprocessing/process.py", line 108, in run
    self._target(*self._args, **self._kwargs)
  File "/home/abr/Airfow/weather/airflow_env/lib/python3.10/site-packages/airflow/dag_processing/processor.py", line 207, in _run_file_processor
    _handle_dag_file_processing()
  File "/home/abr/Airfow/weather/airflow_env/lib/python3.10/site-packages/airflow/dag_processing/processor.py", line 188, in _handle_dag_file_processing
    result: tuple[int, int, int] = dag_file_processor.process_file(
  File "/home/abr/Airfow/weather/airflow_env/lib/python3.10/site-packages/airflow/utils/session.py", line 97, in wrapper
    return func(*args, session=session, **kwargs)
  File "/home/abr/Airfow/weather/airflow_env/lib/python3.10/site-packages/airflow/dag_processing/processor.py", line 942, in process_file
    serialize_errors = DagFileProcessor.save_dag_to_db(
  File "/home/abr/Airfow/weather/airflow_env/lib/python3.10/site-packages/airflow/api_internal/internal_api_call.py", line 166, in wrapper
    return func(*args, **kwargs)
  File "/home/abr/Airfow/weather/airflow_env/lib/python3.10/site-packages/airflow/utils/session.py", line 97, in wrapper
    return func(*args, session=session, **kwargs)
  File "/home/abr/Airfow/weather/airflow_env/lib/python3.10/site-packages/airflow/dag_processing/processor.py", line 982, in save_dag_to_db
    import_errors = DagBag._sync_to_db(dags=dags, processor_subdir=dag_directory, session=session)
  File "/home/abr/Airfow/weather/airflow_env/lib/python3.10/site-packages/airflow/utils/session.py", line 94, in wrapper
    return func(*args, **kwargs)
  File "/home/abr/Airfow/weather/airflow_env/lib/python3.10/site-packages/airflow/models/dagbag.py", line 708, in _sync_to_db
    for attempt in run_with_db_retries(logger=log):
  File "/home/abr/Airfow/weather/airflow_env/lib/python3.10/site-packages/tenacity/__init__.py", line 443, in __iter__
    do = self.iter(retry_state=retry_state)
  File "/home/abr/Airfow/weather/airflow_env/lib/python3.10/site-packages/tenacity/__init__.py", line 376, in iter
    result = action(retry_state)
  File "/home/abr/Airfow/weather/airflow_env/lib/python3.10/site-packages/tenacity/__init__.py", line 398, in <lambda>
    self._add_action_func(lambda rs: rs.outcome.result())
  File "/usr/lib/python3.10/concurrent/futures/_base.py", line 451, in result
    return self.__get_result()
  File "/usr/lib/python3.10/concurrent/futures/_base.py", line 403, in __get_result
    raise self._exception
  File "/home/abr/Airfow/weather/airflow_env/lib/python3.10/site-packages/airflow/models/dagbag.py", line 724, in _sync_to_db
    DAG.bulk_write_to_db(dags.values(), processor_subdir=processor_subdir, session=session)
  File "/home/abr/Airfow/weather/airflow_env/lib/python3.10/site-packages/airflow/utils/session.py", line 94, in wrapper
    return func(*args, **kwargs)
  File "/home/abr/Airfow/weather/airflow_env/lib/python3.10/site-packages/airflow/models/dag.py", line 3252, in bulk_write_to_db
    orm_dags: list[DagModel] = session.scalars(query).unique().all()
  File "/home/abr/Airfow/weather/airflow_env/lib/python3.10/site-packages/sqlalchemy/orm/session.py", line 1778, in scalars
    return self.execute(
  File "/home/abr/Airfow/weather/airflow_env/lib/python3.10/site-packages/sqlalchemy/orm/session.py", line 1716, in execute
    conn = self._connection_for_bind(bind)
  File "/home/abr/Airfow/weather/airflow_env/lib/python3.10/site-packages/sqlalchemy/orm/session.py", line 1555, in _connection_for_bind
    return self._transaction._connection_for_bind(
  File "/home/abr/Airfow/weather/airflow_env/lib/python3.10/site-packages/sqlalchemy/orm/session.py", line 724, in _connection_for_bind
    self._assert_active()
  File "/home/abr/Airfow/weather/airflow_env/lib/python3.10/site-packages/sqlalchemy/orm/session.py", line 604, in _assert_active
    raise sa_exc.PendingRollbackError(
sqlalchemy.exc.PendingRollbackError: This Session's transaction has been rolled back due to a previous exception during flush. To begin a new transaction with this Session, first issue Session.rollback(). Original exception was: (sqlite3.IntegrityError) UNIQUE constraint failed: serialized_dag.dag_id
[SQL: INSERT INTO serialized_dag (dag_id, fileloc, fileloc_hash, data, data_compressed, last_updated, dag_hash, processor_subdir) VALUES (?, ?, ?, ?, ?, ?, ?, ?)]
[parameters: ('example_weekday_branch_operator', '/home/abr/Airfow/weather/airflow_env/lib/python3.10/site-packages/airflow/example_dags/example_branch_day_of_week_operator.py', 16436306062397617, '{"__version": 1, "dag": {"_dag_id": "example_weekday_branch_operator", "schedule_interval": "@daily", "_task_group": {"_group_id": null, "prefix_grou ... (4209 characters truncated) ... module": "airflow.operators.weekday", "_is_empty": false, "start_trigger_args": null}, "__type": "operator"}], "dag_dependencies": [], "params": []}}', None, '2024-12-22 22:19:14.068607', 'e0a4697578484cd394cddb3e843d9a17', '/home/abr/airflow/dags')]
(Background on this error at: https://sqlalche.me/e/14/gkpj) (Background on this error at: https://sqlalche.me/e/14/7s2a)
